<?xml version="1.0" ?>
<robot name="australopithecus_hand_mirror">
  <link name="link_0_0">
    <inertial>
      <origin xyz="0 0 0" rpy="0 0 0"/>
      <mass value="0.1"/>
      <inertia ixx="0.01" ixy="0.0" ixz="0.0" iyy="0.01" iyz="0.0" izz="0.01"/>
    </inertial>
    <visual>
      <origin xyz="0 0 0.024" rpy="0 0 0"/>
      <geometry>
        <mesh filename="/home/zjh/Evolution_PC/Isaaclab_other/agent_for_isaaclab_mirror/mesh/link_0_0_box.stl"/>
      </geometry>
    </visual>
    <collision>
      <origin xyz="0 0 0.024" rpy="0 0 0"/>
      <geometry>
        <mesh filename="/home/zjh/Evolution_PC/Isaaclab_other/agent_for_isaaclab_mirror/mesh/link_0_0_box.stl"/>
      </geometry>
    </collision>
  </link>
  <link name="link_1_0">
    <inertial>
      <origin xyz="0 0 0" rpy="0 0 0"/>
      <mass value="0.1"/>
      <inertia ixx="0.01" ixy="0.0" ixz="0.0" iyy="0.01" iyz="0.0" izz="0.01"/>
    </inertial>
    <visual>
      <origin xyz="0 0 0.024" rpy="0 0 0"/>
      <geometry>
        <mesh filename="/home/zjh/Evolution_PC/Isaaclab_other/agent_for_isaaclab_mirror/mesh/link_1_0_capsule.stl"/>
      </geometry>
    </visual>
    <collision>
      <origin xyz="0 0 0.024" rpy="0 0 0"/>
      <geometry>
        <mesh filename="/home/zjh/Evolution_PC/Isaaclab_other/agent_for_isaaclab_mirror/mesh/link_1_0_capsule.stl"/>
      </geometry>
    </collision>
  </link>
  <link name="link_1_1">
    <inertial>
      <origin xyz="0 0 0" rpy="0 0 0"/>
      <mass value="0.1"/>
      <inertia ixx="0.01" ixy="0.0" ixz="0.0" iyy="0.01" iyz="0.0" izz="0.01"/>
    </inertial>
    <visual>
      <origin xyz="0 0 0.014" rpy="0 0 0"/>
      <geometry>
        <mesh filename="/home/zjh/Evolution_PC/Isaaclab_other/agent_for_isaaclab_mirror/mesh/link_1_1_capsule.stl"/>
      </geometry>
    </visual>
    <collision>
      <origin xyz="0 0 0.014" rpy="0 0 0"/>
      <geometry>
        <mesh filename="/home/zjh/Evolution_PC/Isaaclab_other/agent_for_isaaclab_mirror/mesh/link_1_1_capsule.stl"/>
      </geometry>
    </collision>
  </link>
  <link name="link_1_2">
    <inertial>
      <origin xyz="0 0 0" rpy="0 0 0"/>
      <mass value="0.1"/>
      <inertia ixx="0.01" ixy="0.0" ixz="0.0" iyy="0.01" iyz="0.0" izz="0.01"/>
    </inertial>
    <visual>
      <origin xyz="0 0 0.0095" rpy="0 0 0"/>
      <geometry>
        <mesh filename="/home/zjh/Evolution_PC/Isaaclab_other/agent_for_isaaclab_mirror/mesh/link_1_2_capsule.stl"/>
      </geometry>
    </visual>
    <collision>
      <origin xyz="0 0 0.0095" rpy="0 0 0"/>
      <geometry>
        <mesh filename="/home/zjh/Evolution_PC/Isaaclab_other/agent_for_isaaclab_mirror/mesh/link_1_2_capsule.stl"/>
      </geometry>
    </collision>
  </link>
  <link name="link_2_0">
    <inertial>
      <origin xyz="0 0 0" rpy="0 0 0"/>
      <mass value="0.1"/>
      <inertia ixx="0.01" ixy="0.0" ixz="0.0" iyy="0.01" iyz="0.0" izz="0.01"/>
    </inertial>
    <visual>
      <origin xyz="0 0 0.021" rpy="0 0 0"/>
      <geometry>
        <mesh filename="/home/zjh/Evolution_PC/Isaaclab_other/agent_for_isaaclab_mirror/mesh/link_2_0_capsule.stl"/>
      </geometry>
    </visual>
    <collision>
      <origin xyz="0 0 0.021" rpy="0 0 0"/>
      <geometry>
        <mesh filename="/home/zjh/Evolution_PC/Isaaclab_other/agent_for_isaaclab_mirror/mesh/link_2_0_capsule.stl"/>
      </geometry>
    </collision>
  </link>
  <link name="link_2_1">
    <inertial>
      <origin xyz="0 0 0" rpy="0 0 0"/>
      <mass value="0.1"/>
      <inertia ixx="0.01" ixy="0.0" ixz="0.0" iyy="0.01" iyz="0.0" izz="0.01"/>
    </inertial>
    <visual>
      <origin xyz="0 0 0.0135" rpy="0 0 0"/>
      <geometry>
        <mesh filename="/home/zjh/Evolution_PC/Isaaclab_other/agent_for_isaaclab_mirror/mesh/link_2_1_capsule.stl"/>
      </geometry>
    </visual>
    <collision>
      <origin xyz="0 0 0.0135" rpy="0 0 0"/>
      <geometry>
        <mesh filename="/home/zjh/Evolution_PC/Isaaclab_other/agent_for_isaaclab_mirror/mesh/link_2_1_capsule.stl"/>
      </geometry>
    </collision>
  </link>
  <link name="link_2_2">
    <inertial>
      <origin xyz="0 0 0" rpy="0 0 0"/>
      <mass value="0.1"/>
      <inertia ixx="0.01" ixy="0.0" ixz="0.0" iyy="0.01" iyz="0.0" izz="0.01"/>
    </inertial>
    <visual>
      <origin xyz="0 0 0.009" rpy="0 0 0"/>
      <geometry>
        <mesh filename="/home/zjh/Evolution_PC/Isaaclab_other/agent_for_isaaclab_mirror/mesh/link_2_2_capsule.stl"/>
      </geometry>
    </visual>
    <collision>
      <origin xyz="0 0 0.009" rpy="0 0 0"/>
      <geometry>
        <mesh filename="/home/zjh/Evolution_PC/Isaaclab_other/agent_for_isaaclab_mirror/mesh/link_2_2_capsule.stl"/>
      </geometry>
    </collision>
  </link>
  <link name="link_2_3">
    <inertial>
      <origin xyz="0 0 0" rpy="0 0 0"/>
      <mass value="0.1"/>
      <inertia ixx="0.01" ixy="0.0" ixz="0.0" iyy="0.01" iyz="0.0" izz="0.01"/>
    </inertial>
    <visual>
      <origin xyz="0 0 0.0065" rpy="0 0 0"/>
      <geometry>
        <mesh filename="/home/zjh/Evolution_PC/Isaaclab_other/agent_for_isaaclab_mirror/mesh/link_2_3_capsule.stl"/>
      </geometry>
    </visual>
    <collision>
      <origin xyz="0 0 0.0065" rpy="0 0 0"/>
      <geometry>
        <mesh filename="/home/zjh/Evolution_PC/Isaaclab_other/agent_for_isaaclab_mirror/mesh/link_2_3_capsule.stl"/>
      </geometry>
    </collision>
  </link>
  <link name="link_3_0">
    <inertial>
      <origin xyz="0 0 0" rpy="0 0 0"/>
      <mass value="0.1"/>
      <inertia ixx="0.01" ixy="0.0" ixz="0.0" iyy="0.01" iyz="0.0" izz="0.01"/>
    </inertial>
    <visual>
      <origin xyz="0 0 0.0225" rpy="0 0 0"/>
      <geometry>
        <mesh filename="/home/zjh/Evolution_PC/Isaaclab_other/agent_for_isaaclab_mirror/mesh/link_3_0_capsule.stl"/>
      </geometry>
    </visual>
    <collision>
      <origin xyz="0 0 0.0225" rpy="0 0 0"/>
      <geometry>
        <mesh filename="/home/zjh/Evolution_PC/Isaaclab_other/agent_for_isaaclab_mirror/mesh/link_3_0_capsule.stl"/>
      </geometry>
    </collision>
  </link>
  <link name="link_3_1">
    <inertial>
      <origin xyz="0 0 0" rpy="0 0 0"/>
      <mass value="0.1"/>
      <inertia ixx="0.01" ixy="0.0" ixz="0.0" iyy="0.01" iyz="0.0" izz="0.01"/>
    </inertial>
    <visual>
      <origin xyz="0 0 0.0145" rpy="0 0 0"/>
      <geometry>
        <mesh filename="/home/zjh/Evolution_PC/Isaaclab_other/agent_for_isaaclab_mirror/mesh/link_3_1_capsule.stl"/>
      </geometry>
    </visual>
    <collision>
      <origin xyz="0 0 0.0145" rpy="0 0 0"/>
      <geometry>
        <mesh filename="/home/zjh/Evolution_PC/Isaaclab_other/agent_for_isaaclab_mirror/mesh/link_3_1_capsule.stl"/>
      </geometry>
    </collision>
  </link>
  <link name="link_3_2">
    <inertial>
      <origin xyz="0 0 0" rpy="0 0 0"/>
      <mass value="0.1"/>
      <inertia ixx="0.01" ixy="0.0" ixz="0.0" iyy="0.01" iyz="0.0" izz="0.01"/>
    </inertial>
    <visual>
      <origin xyz="0 0 0.0105" rpy="0 0 0"/>
      <geometry>
        <mesh filename="/home/zjh/Evolution_PC/Isaaclab_other/agent_for_isaaclab_mirror/mesh/link_3_2_capsule.stl"/>
      </geometry>
    </visual>
    <collision>
      <origin xyz="0 0 0.0105" rpy="0 0 0"/>
      <geometry>
        <mesh filename="/home/zjh/Evolution_PC/Isaaclab_other/agent_for_isaaclab_mirror/mesh/link_3_2_capsule.stl"/>
      </geometry>
    </collision>
  </link>
  <link name="link_3_3">
    <inertial>
      <origin xyz="0 0 0" rpy="0 0 0"/>
      <mass value="0.1"/>
      <inertia ixx="0.01" ixy="0.0" ixz="0.0" iyy="0.01" iyz="0.0" izz="0.01"/>
    </inertial>
    <visual>
      <origin xyz="0 0 0.007" rpy="0 0 0"/>
      <geometry>
        <mesh filename="/home/zjh/Evolution_PC/Isaaclab_other/agent_for_isaaclab_mirror/mesh/link_3_3_capsule.stl"/>
      </geometry>
    </visual>
    <collision>
      <origin xyz="0 0 0.007" rpy="0 0 0"/>
      <geometry>
        <mesh filename="/home/zjh/Evolution_PC/Isaaclab_other/agent_for_isaaclab_mirror/mesh/link_3_3_capsule.stl"/>
      </geometry>
    </collision>
  </link>
  <link name="link_4_0">
    <inertial>
      <origin xyz="0 0 0" rpy="0 0 0"/>
      <mass value="0.1"/>
      <inertia ixx="0.01" ixy="0.0" ixz="0.0" iyy="0.01" iyz="0.0" izz="0.01"/>
    </inertial>
    <visual>
      <origin xyz="0 0 0.021" rpy="0 0 0"/>
      <geometry>
        <mesh filename="/home/zjh/Evolution_PC/Isaaclab_other/agent_for_isaaclab_mirror/mesh/link_4_0_capsule.stl"/>
      </geometry>
    </visual>
    <collision>
      <origin xyz="0 0 0.021" rpy="0 0 0"/>
      <geometry>
        <mesh filename="/home/zjh/Evolution_PC/Isaaclab_other/agent_for_isaaclab_mirror/mesh/link_4_0_capsule.stl"/>
      </geometry>
    </collision>
  </link>
  <link name="link_4_1">
    <inertial>
      <origin xyz="0 0 0" rpy="0 0 0"/>
      <mass value="0.1"/>
      <inertia ixx="0.01" ixy="0.0" ixz="0.0" iyy="0.01" iyz="0.0" izz="0.01"/>
    </inertial>
    <visual>
      <origin xyz="0 0 0.0135" rpy="0 0 0"/>
      <geometry>
        <mesh filename="/home/zjh/Evolution_PC/Isaaclab_other/agent_for_isaaclab_mirror/mesh/link_4_1_capsule.stl"/>
      </geometry>
    </visual>
    <collision>
      <origin xyz="0 0 0.0135" rpy="0 0 0"/>
      <geometry>
        <mesh filename="/home/zjh/Evolution_PC/Isaaclab_other/agent_for_isaaclab_mirror/mesh/link_4_1_capsule.stl"/>
      </geometry>
    </collision>
  </link>
  <link name="link_4_2">
    <inertial>
      <origin xyz="0 0 0" rpy="0 0 0"/>
      <mass value="0.1"/>
      <inertia ixx="0.01" ixy="0.0" ixz="0.0" iyy="0.01" iyz="0.0" izz="0.01"/>
    </inertial>
    <visual>
      <origin xyz="0 0 0.009" rpy="0 0 0"/>
      <geometry>
        <mesh filename="/home/zjh/Evolution_PC/Isaaclab_other/agent_for_isaaclab_mirror/mesh/link_4_2_capsule.stl"/>
      </geometry>
    </visual>
    <collision>
      <origin xyz="0 0 0.009" rpy="0 0 0"/>
      <geometry>
        <mesh filename="/home/zjh/Evolution_PC/Isaaclab_other/agent_for_isaaclab_mirror/mesh/link_4_2_capsule.stl"/>
      </geometry>
    </collision>
  </link>
  <link name="link_4_3">
    <inertial>
      <origin xyz="0 0 0" rpy="0 0 0"/>
      <mass value="0.1"/>
      <inertia ixx="0.01" ixy="0.0" ixz="0.0" iyy="0.01" iyz="0.0" izz="0.01"/>
    </inertial>
    <visual>
      <origin xyz="0 0 0.0065" rpy="0 0 0"/>
      <geometry>
        <mesh filename="/home/zjh/Evolution_PC/Isaaclab_other/agent_for_isaaclab_mirror/mesh/link_4_3_capsule.stl"/>
      </geometry>
    </visual>
    <collision>
      <origin xyz="0 0 0.0065" rpy="0 0 0"/>
      <geometry>
        <mesh filename="/home/zjh/Evolution_PC/Isaaclab_other/agent_for_isaaclab_mirror/mesh/link_4_3_capsule.stl"/>
      </geometry>
    </collision>
  </link>
  <link name="link_5_0">
    <inertial>
      <origin xyz="0 0 0" rpy="0 0 0"/>
      <mass value="0.1"/>
      <inertia ixx="0.01" ixy="0.0" ixz="0.0" iyy="0.01" iyz="0.0" izz="0.01"/>
    </inertial>
    <visual>
      <origin xyz="0 0 0.018" rpy="0 0 0"/>
      <geometry>
        <mesh filename="/home/zjh/Evolution_PC/Isaaclab_other/agent_for_isaaclab_mirror/mesh/link_5_0_capsule.stl"/>
      </geometry>
    </visual>
    <collision>
      <origin xyz="0 0 0.018" rpy="0 0 0"/>
      <geometry>
        <mesh filename="/home/zjh/Evolution_PC/Isaaclab_other/agent_for_isaaclab_mirror/mesh/link_5_0_capsule.stl"/>
      </geometry>
    </collision>
  </link>
  <link name="link_5_1">
    <inertial>
      <origin xyz="0 0 0" rpy="0 0 0"/>
      <mass value="0.1"/>
      <inertia ixx="0.01" ixy="0.0" ixz="0.0" iyy="0.01" iyz="0.0" izz="0.01"/>
    </inertial>
    <visual>
      <origin xyz="0 0 0.01" rpy="0 0 0"/>
      <geometry>
        <mesh filename="/home/zjh/Evolution_PC/Isaaclab_other/agent_for_isaaclab_mirror/mesh/link_5_1_capsule.stl"/>
      </geometry>
    </visual>
    <collision>
      <origin xyz="0 0 0.01" rpy="0 0 0"/>
      <geometry>
        <mesh filename="/home/zjh/Evolution_PC/Isaaclab_other/agent_for_isaaclab_mirror/mesh/link_5_1_capsule.stl"/>
      </geometry>
    </collision>
  </link>
  <link name="link_5_2">
    <inertial>
      <origin xyz="0 0 0" rpy="0 0 0"/>
      <mass value="0.1"/>
      <inertia ixx="0.01" ixy="0.0" ixz="0.0" iyy="0.01" iyz="0.0" izz="0.01"/>
    </inertial>
    <visual>
      <origin xyz="0 0 0.007" rpy="0 0 0"/>
      <geometry>
        <mesh filename="/home/zjh/Evolution_PC/Isaaclab_other/agent_for_isaaclab_mirror/mesh/link_5_2_capsule.stl"/>
      </geometry>
    </visual>
    <collision>
      <origin xyz="0 0 0.007" rpy="0 0 0"/>
      <geometry>
        <mesh filename="/home/zjh/Evolution_PC/Isaaclab_other/agent_for_isaaclab_mirror/mesh/link_5_2_capsule.stl"/>
      </geometry>
    </collision>
  </link>
  <link name="link_5_3">
    <inertial>
      <origin xyz="0 0 0" rpy="0 0 0"/>
      <mass value="0.1"/>
      <inertia ixx="0.01" ixy="0.0" ixz="0.0" iyy="0.01" iyz="0.0" izz="0.01"/>
    </inertial>
    <visual>
      <origin xyz="0 0 0.0055" rpy="0 0 0"/>
      <geometry>
        <mesh filename="/home/zjh/Evolution_PC/Isaaclab_other/agent_for_isaaclab_mirror/mesh/link_5_3_capsule.stl"/>
      </geometry>
    </visual>
    <collision>
      <origin xyz="0 0 0.0055" rpy="0 0 0"/>
      <geometry>
        <mesh filename="/home/zjh/Evolution_PC/Isaaclab_other/agent_for_isaaclab_mirror/mesh/link_5_3_capsule.stl"/>
      </geometry>
    </collision>
  </link>
  <joint name="link_0_0_to_link_1_0" type="revolute">
    <parent link="link_0_0"/>
    <child link="link_1_0"/>
    <origin xyz="-0.013 0.0 0.006" rpy="0.12 -2.04 0.18"/>
    <axis xyz="1 0 0"/>
    <limit lower="0.0" upper="1.2" effort="18.0" velocity="2.2"/>
  </joint>
  <joint name="link_1_0_to_link_1_1" type="revolute">
    <parent link="link_1_0"/>
    <child link="link_1_1"/>
    <origin xyz="0 0 0.052" rpy="0.16 -0.0 -0.0"/>
    <axis xyz="1 0 0"/>
    <limit lower="0.0" upper="1.35" effort="12.0" velocity="1.8"/>
  </joint>
  <joint name="link_1_1_to_link_1_2" type="revolute">
    <parent link="link_1_1"/>
    <child link="link_1_2"/>
    <origin xyz="0 0 0.032" rpy="0.14 -0.0 -0.0"/>
    <axis xyz="1 0 0"/>
    <limit lower="0.0" upper="1.05" effort="7.0" velocity="1.6"/>
  </joint>
  <joint name="link_0_0_to_link_2_0" type="revolute">
    <parent link="link_0_0"/>
    <child link="link_2_0"/>
    <origin xyz="-0.017 0.0 0.013" rpy="0.05 -1.73 -0.08"/>
    <axis xyz="1 0 0"/>
    <limit lower="0.0" upper="1.05" effort="16.0" velocity="2.0"/>
  </joint>
  <joint name="link_2_0_to_link_2_1" type="revolute">
    <parent link="link_2_0"/>
    <child link="link_2_1"/>
    <origin xyz="0 0 0.0462" rpy="0.1 -0.0 -0.0"/>
    <axis xyz="1 0 0"/>
    <limit lower="0.0" upper="1.45" effort="11.0" velocity="1.7"/>
  </joint>
  <joint name="link_2_1_to_link_2_2" type="revolute">
    <parent link="link_2_1"/>
    <child link="link_2_2"/>
    <origin xyz="0 0 0.0309" rpy="0.11 -0.0 -0.0"/>
    <axis xyz="1 0 0"/>
    <limit lower="0.0" upper="1.25" effort="6.0" velocity="1.5"/>
  </joint>
  <joint name="link_2_2_to_link_2_3" type="revolute">
    <parent link="link_2_2"/>
    <child link="link_2_3"/>
    <origin xyz="0 0 0.0214" rpy="0.08 -0.0 -0.0"/>
    <axis xyz="1 0 0"/>
    <limit lower="0.0" upper="1.0" effort="5.0" velocity="1.4"/>
  </joint>
  <joint name="link_0_0_to_link_3_0" type="revolute">
    <parent link="link_0_0"/>
    <child link="link_3_0"/>
    <origin xyz="-0.017 0.0 0.024" rpy="0.05 -1.6 -0.02"/>
    <axis xyz="1 0 0"/>
    <limit lower="0.0" upper="1.05" effort="16.0" velocity="2.0"/>
  </joint>
  <joint name="link_3_0_to_link_3_1" type="revolute">
    <parent link="link_3_0"/>
    <child link="link_3_1"/>
    <origin xyz="0 0 0.0494" rpy="0.12 -0.0 -0.0"/>
    <axis xyz="1 0 0"/>
    <limit lower="0.0" upper="1.45" effort="11.0" velocity="1.7"/>
  </joint>
  <joint name="link_3_1_to_link_3_2" type="revolute">
    <parent link="link_3_1"/>
    <child link="link_3_2"/>
    <origin xyz="0 0 0.0331" rpy="0.13 -0.0 -0.0"/>
    <axis xyz="1 0 0"/>
    <limit lower="0.0" upper="1.25" effort="6.0" velocity="1.5"/>
  </joint>
  <joint name="link_3_2_to_link_3_3" type="revolute">
    <parent link="link_3_2"/>
    <child link="link_3_3"/>
    <origin xyz="0 0 0.0247" rpy="0.1 -0.0 -0.0"/>
    <axis xyz="1 0 0"/>
    <limit lower="0.0" upper="1.0" effort="5.0" velocity="1.4"/>
  </joint>
  <joint name="link_0_0_to_link_4_0" type="revolute">
    <parent link="link_0_0"/>
    <child link="link_4_0"/>
    <origin xyz="-0.016 0.0 0.034" rpy="0.06 -1.48 0.04"/>
    <axis xyz="1 0 0"/>
    <limit lower="0.0" upper="1.05" effort="15.0" velocity="2.0"/>
  </joint>
  <joint name="link_4_0_to_link_4_1" type="revolute">
    <parent link="link_4_0"/>
    <child link="link_4_1"/>
    <origin xyz="0 0 0.046" rpy="0.15 -0.0 -0.0"/>
    <axis xyz="1 0 0"/>
    <limit lower="0.0" upper="1.45" effort="10.0" velocity="1.7"/>
  </joint>
  <joint name="link_4_1_to_link_4_2" type="revolute">
    <parent link="link_4_1"/>
    <child link="link_4_2"/>
    <origin xyz="0 0 0.0308" rpy="0.16 -0.0 -0.0"/>
    <axis xyz="1 0 0"/>
    <limit lower="0.0" upper="1.25" effort="6.0" velocity="1.5"/>
  </joint>
  <joint name="link_4_2_to_link_4_3" type="revolute">
    <parent link="link_4_2"/>
    <child link="link_4_3"/>
    <origin xyz="0 0 0.0214" rpy="0.12 -0.0 -0.0"/>
    <axis xyz="1 0 0"/>
    <limit lower="0.0" upper="1.0" effort="5.0" velocity="1.4"/>
  </joint>
  <joint name="link_0_0_to_link_5_0" type="revolute">
    <parent link="link_0_0"/>
    <child link="link_5_0"/>
    <origin xyz="-0.014 0.0 0.043" rpy="0.08 -1.36 0.1"/>
    <axis xyz="1 0 0"/>
    <limit lower="0.0" upper="1.0" effort="14.0" velocity="1.9"/>
  </joint>
  <joint name="link_5_0_to_link_5_1" type="revolute">
    <parent link="link_5_0"/>
    <child link="link_5_1"/>
    <origin xyz="0 0 0.0397" rpy="0.18 -0.0 -0.0"/>
    <axis xyz="1 0 0"/>
    <limit lower="0.0" upper="1.35" effort="9.0" velocity="1.6"/>
  </joint>
  <joint name="link_5_1_to_link_5_2" type="revolute">
    <parent link="link_5_1"/>
    <child link="link_5_2"/>
    <origin xyz="0 0 0.0235" rpy="0.18 -0.0 -0.0"/>
    <axis xyz="1 0 0"/>
    <limit lower="0.0" upper="1.15" effort="5.0" velocity="1.4"/>
  </joint>
  <joint name="link_5_2_to_link_5_3" type="revolute">
    <parent link="link_5_2"/>
    <child link="link_5_3"/>
    <origin xyz="0 0 0.0171" rpy="0.14 -0.0 -0.0"/>
    <axis xyz="1 0 0"/>
    <limit lower="0.0" upper="0.95" effort="4.0" velocity="1.3"/>
  </joint>
</robot>
